Workbook

Sheet Dashboard
B1: PERSONAL PREPARATION DASHBOARD PANEL
B4: Overall Progress | D4: Completed Modules | F4: In Progress Modules | H4: Not Started Modules
B5: =COUNTIF(Tracker!D:D, "Completed") / 138 -> 0 | D5: =COUNTIF(Tracker!D:D, "Completed") -> 0 | F5: =COUNTIF(Tracker!D:D, "In Progress") -> 0 | H5: =COUNTIF(Tracker!D:D, "Not Started") -> 138
B7: Category Performance Overview
B9: Subject Category | C9: Total Modules | D9: Completed Modules | E9: Completion Rate | U9: Status | V9: Count
B10: Software Engineering | C10: =COUNTA(Tracker!C3:C32) -> 30 | D10: =COUNTIF(Tracker!D3:D32, "Completed") -> 0 | E10: =D10/C10 -> 0 | U10: Completed | V10: =COUNTIF(Tracker!D:D, "Completed") -> 0
B11: AI | C11: =COUNTA(Tracker!C36:C65) -> 30 | D11: =COUNTIF(Tracker!D36:D65, "Completed") -> 0 | E11: =D11/C11 -> 0 | U11: In Progress | V11: =COUNTIF(Tracker!D:D, "In Progress") -> 0
B12: Core CS | C12: =COUNTA(Tracker!C69:C92) -> 24 | D12: =COUNTIF(Tracker!D69:D92, "Completed") -> 0 | E12: =D12/C12 -> 0 | U12: Not Started | V12: =COUNTIF(Tracker!D:D, "Not Started") -> 138
B13: Aptitude | C13: =COUNTA(Tracker!C96:C107) -> 12 | D13: =COUNTIF(Tracker!D96:D107, "Completed") -> 0 | E13: =D13/C13 -> 0
B14: Web Development | C14: =COUNTA(Tracker!C111:C152) -> 42 | D14: =COUNTIF(Tracker!D111:D152, "Completed") -> 0 | E14: =D14/C14 -> 0
B15: Overall Summary | C15: =SUM(C10:C14) -> 138 | D15: =SUM(D10:D14) -> 0 | E15: =D15/C15 -> 0
B17: Insights & Statistics
B18: Total Subjects | D18: 23
B19: Completed (100% Progress) 🏆 | D19: =COUNTIF(Tracker!J2:J24, 1) -> 0
B20: In Progress (>=80% Near Completion) ⚡ | D20: =COUNTIFS(Tracker!J2:J24, ">=0.8", Tracker!J2:J24, "<1") -> 0
B21: Not Started yet ⏳ | D21: =COUNTIF(Tracker!J2:J24, 0) -> 23
B23: Motivational Insight
B24: "The expert in anything was once a beginner." - Helen Hayes Preparation Tracking Active • Current Date: 2026-06-22
B28: Recommended Weekly Preparation Flow
B29: Week | C29: Subject Focus | D29: Modules | E29: Key Focus Area
B30: Week 1-4 | C30: Java & DSA | D30: Modules 1-5 | E30: Syntax, OOP, Collections, Lists/Trees
B31: Week 5-8 | C31: Core CS & ML | D31: Modules 1-5 | E31: DBMS, SQL Queries, OS Threads, ML Regression
B32: Week 9-12 | C32: Systems & NLP | D32: Modules 1-5 | E32: Spring Boot, System Design, NLP Models
B33: Week 13-16 | C33: Advanced AI | D33: Modules 1-5 | E33: GenAI, RAG Pipelines, LoRA, PEFT Tuning
B35: Daily Preparation & Study Habits Checklist
B36: Activity | C36: Daily Target | D36: Mode | E36: Frequency
B37: Coding Practice | C37: 2 LeetCode Problems | D37: Practical | E37: Daily
B38: Theory Revision | C38: 30 Minutes Review | D38: Reading | E38: Alternate Days
B39: Interview Prep | C39: 1 Mock Topic Viva | D39: Verbal | E39: Daily
B40: Note Updates | C40: Document Key Concepts | D40: Active Recall | E40: Weekly

Sheet Subject Map
A1: Subject Category | B1: Software Engineering | C1: AI | D1: Core CS | E1: Aptitude | F1: Web Development
A2: Subject Name | B2: Java | C2: Machine Learning | D2: DBMS | E2: Quantitative Aptitude | F2: HTML CSS Git
B3: OOP | C3: Deep Learning | D3: SQL | E3: Verbal Aptitude | F3: JavaScript
B4: DSA | C4: NLP | D4: OS | F4: CSS Frameworks
B5: SpringBoot | C5: GenAI | D5: CN | F5: ReactJS
B6: System Design | C6: AI Agents | F6: NodeJS ExpressJS
F7: TypeScript
F8: NextJS

Sheet Tracker
A1: SOFTWARE ENGINEERING PROGRESS TRACKER | H1: Subject | I1: Category | J1: Completion % | K1: Progress Bar
A2: Category | B2: Subject | C2: Module | D2: Status | E2: Confidence | F2: Side Note | H2: Java | I2: Software Engineering | J2: =COUNTIF(D3:D8, "Completed") / 6 -> 0 | K2: =REPT("■", ROUND(J2*10,0)) & REPT("□", 10-ROUND(J2*10,0)) -> □□□□□□□□□□
A3: Software Engineering | B3: Java | C3: Module 1 | D3: Not Started | E3: Low | H3: OOP | I3: Software Engineering | J3: =COUNTIF(D9:D14, "Completed") / 6 -> 0 | K3: =REPT("■", ROUND(J3*10,0)) & REPT("□", 10-ROUND(J3*10,0)) -> □□□□□□□□□□
C4: Module 2 | D4: Not Started | E4: Low | H4: DSA | I4: Software Engineering | J4: =COUNTIF(D15:D20, "Completed") / 6 -> 0 | K4: =REPT("■", ROUND(J4*10,0)) & REPT("□", 10-ROUND(J4*10,0)) -> □□□□□□□□□□
C5: Module 3 | D5: Not Started | E5: Low | H5: SpringBoot | I5: Software Engineering | J5: =COUNTIF(D21:D26, "Completed") / 6 -> 0 | K5: =REPT("■", ROUND(J5*10,0)) & REPT("□", 10-ROUND(J5*10,0)) -> □□□□□□□□□□
C6: Module 4 | D6: Not Started | E6: Low | H6: System Design | I6: Software Engineering | J6: =COUNTIF(D27:D32, "Completed") / 6 -> 0 | K6: =REPT("■", ROUND(J6*10,0)) & REPT("□", 10-ROUND(J6*10,0)) -> □□□□□□□□□□
C7: Module 5 | D7: Not Started | E7: Low | H7: Machine Learning | I7: AI | J7: =COUNTIF(D36:D41, "Completed") / 6 -> 0 | K7: =REPT("■", ROUND(J7*10,0)) & REPT("□", 10-ROUND(J7*10,0)) -> □□□□□□□□□□
C8: Interview Preparation & Revision | D8: Not Started | E8: Low | H8: Deep Learning | I8: AI | J8: =COUNTIF(D42:D47, "Completed") / 6 -> 0 | K8: =REPT("■", ROUND(J8*10,0)) & REPT("□", 10-ROUND(J8*10,0)) -> □□□□□□□□□□
B9: OOP | C9: Module 1 | D9: Not Started | E9: Low | H9: NLP | I9: AI | J9: =COUNTIF(D48:D53, "Completed") / 6 -> 0 | K9: =REPT("■", ROUND(J9*10,0)) & REPT("□", 10-ROUND(J9*10,0)) -> □□□□□□□□□□
C10: Module 2 | D10: Not Started | E10: Low | H10: GenAI | I10: AI | J10: =COUNTIF(D54:D59, "Completed") / 6 -> 0 | K10: =REPT("■", ROUND(J10*10,0)) & REPT("□", 10-ROUND(J10*10,0)) -> □□□□□□□□□□
C11: Module 3 | D11: Not Started | E11: Low | H11: AI Agents | I11: AI | J11: =COUNTIF(D60:D65, "Completed") / 6 -> 0 | K11: =REPT("■", ROUND(J11*10,0)) & REPT("□", 10-ROUND(J11*10,0)) -> □□□□□□□□□□
C12: Module 4 | D12: Not Started | E12: Low | H12: DBMS | I12: Core CS | J12: =COUNTIF(D69:D74, "Completed") / 6 -> 0 | K12: =REPT("■", ROUND(J12*10,0)) & REPT("□", 10-ROUND(J12*10,0)) -> □□□□□□□□□□
C13: Module 5 | D13: Not Started | E13: Low | H13: SQL | I13: Core CS | J13: =COUNTIF(D75:D80, "Completed") / 6 -> 0 | K13: =REPT("■", ROUND(J13*10,0)) & REPT("□", 10-ROUND(J13*10,0)) -> □□□□□□□□□□
C14: Interview Preparation & Revision | D14: Not Started | E14: Low | H14: OS | I14: Core CS | J14: =COUNTIF(D81:D86, "Completed") / 6 -> 0 | K14: =REPT("■", ROUND(J14*10,0)) & REPT("□", 10-ROUND(J14*10,0)) -> □□□□□□□□□□
B15: DSA | C15: Module 1 | D15: Not Started | E15: Low | H15: CN | I15: Core CS | J15: =COUNTIF(D87:D92, "Completed") / 6 -> 0 | K15: =REPT("■", ROUND(J15*10,0)) & REPT("□", 10-ROUND(J15*10,0)) -> □□□□□□□□□□
C16: Module 2 | D16: Not Started | E16: Low | H16: Quantitative Aptitude | I16: Aptitude | J16: =COUNTIF(D96:D101, "Completed") / 6 -> 0 | K16: =REPT("■", ROUND(J16*10,0)) & REPT("□", 10-ROUND(J16*10,0)) -> □□□□□□□□□□
C17: Module 3 | D17: Not Started | E17: Low | H17: Verbal Aptitude | I17: Aptitude | J17: =COUNTIF(D102:D107, "Completed") / 6 -> 0 | K17: =REPT("■", ROUND(J17*10,0)) & REPT("□", 10-ROUND(J17*10,0)) -> □□□□□□□□□□
C18: Module 4 | D18: Not Started | E18: Low | H18: HTML CSS Git | I18: Web Development | J18: =COUNTIF(D111:D116, "Completed") / 6 -> 0 | K18: =REPT("■", ROUND(J18*10,0)) & REPT("□", 10-ROUND(J18*10,0)) -> □□□□□□□□□□
C19: Module 5 | D19: Not Started | E19: Low | H19: JavaScript | I19: Web Development | J19: =COUNTIF(D117:D122, "Completed") / 6 -> 0 | K19: =REPT("■", ROUND(J19*10,0)) & REPT("□", 10-ROUND(J19*10,0)) -> □□□□□□□□□□
C20: Interview Preparation & Revision | D20: Not Started | E20: Low | H20: CSS Frameworks | I20: Web Development | J20: =COUNTIF(D123:D128, "Completed") / 6 -> 0 | K20: =REPT("■", ROUND(J20*10,0)) & REPT("□", 10-ROUND(J20*10,0)) -> □□□□□□□□□□
B21: SpringBoot | C21: Module 1 | D21: Not Started | E21: Low | H21: ReactJS | I21: Web Development | J21: =COUNTIF(D129:D134, "Completed") / 6 -> 0 | K21: =REPT("■", ROUND(J21*10,0)) & REPT("□", 10-ROUND(J21*10,0)) -> □□□□□□□□□□
C22: Module 2 | D22: Not Started | E22: Low | H22: NodeJS ExpressJS | I22: Web Development | J22: =COUNTIF(D135:D140, "Completed") / 6 -> 0 | K22: =REPT("■", ROUND(J22*10,0)) & REPT("□", 10-ROUND(J22*10,0)) -> □□□□□□□□□□
C23: Module 3 | D23: Not Started | E23: Low | H23: TypeScript | I23: Web Development | J23: =COUNTIF(D141:D146, "Completed") / 6 -> 0 | K23: =REPT("■", ROUND(J23*10,0)) & REPT("□", 10-ROUND(J23*10,0)) -> □□□□□□□□□□
C24: Module 4 | D24: Not Started | E24: Low | H24: NextJS | I24: Web Development | J24: =COUNTIF(D147:D152, "Completed") / 6 -> 0 | K24: =REPT("■", ROUND(J24*10,0)) & REPT("□", 10-ROUND(J24*10,0)) -> □□□□□□□□□□
C25: Module 5 | D25: Not Started | E25: Low | H25: Status | I25: Count
C26: Interview Preparation & Revision | D26: Not Started | E26: Low | H26: Completed | I26: =COUNTIF(D:D, "Completed") -> 0
B27: System Design | C27: Module 1 | D27: Not Started | E27: Low | H27: In Progress | I27: =COUNTIF(D:D, "In Progress") -> 0
C28: Module 2 | D28: Not Started | E28: Low | H28: Not Started | I28: =COUNTIF(D:D, "Not Started") -> 138
C29: Module 3 | D29: Not Started | E29: Low
C30: Module 4 | D30: Not Started | E30: Low
C31: Module 5 | D31: Not Started | E31: Low
C32: Interview Preparation & Revision | D32: Not Started | E32: Low
A34: AI PROGRESS TRACKER
A35: Category | B35: Subject | C35: Module | D35: Status | E35: Confidence | F35: Side Note
A36: AI | B36: Machine Learning | C36: Module 1 | D36: Not Started | E36: Low
C37: Module 2 | D37: Not Started | E37: Low
C38: Module 3 | D38: Not Started | E38: Low
C39: Module 4 | D39: Not Started | E39: Low
C40: Module 5 | D40: Not Started | E40: Low
C41: Interview Preparation & Revision | D41: Not Started | E41: Low
...

Sheet Software Engineering
A1: SOFTWARE ENG - LEARNING ARCHITECTURE
A2: Module | B2: Java | C2: OOP | D2: DSA | E2: SpringBoot | F2: System Design
A3: Module 1 | B3: • History of Java & Platform Independence: javac Compiler, JVM execution engine, JIT compilation, Bytecode verification. • JVM Memory Architecture: Heap, Stack, Method Area, Metaspace layout, PC Registers, Native Method Stack. • String Constant Pool (SCP) memory allocation, String Immutability reasoning, Garbage Collection basics (reachability). • Variables & Scope: Primitive vs Reference types, implicit/explicit narrowing casting, precision loss rules. • Operators & Control Flow: Arithmetic/Logical/Bitwise logic, loops (for, while, do-while), break/continue. | C3: • Programming Paradigms: Procedural, Object-Oriented, Functional, Event-driven modeling comparison. • Object-Oriented Thinking: Objects, attributes, behaviors, identity, real-world entity abstraction. • Class Design: Fields, methods, constructors, encapsulation boundaries, getters/setters. • Abstraction: Implementation hiding, Interfaces, Abstract Classes, Abstract Class vs Interface trade-offs. • Object Relationships: Association, Aggregation (weak ownership), Composition (strong lifecycle ownership), Dependency. | D3: • Complexity Analysis: Asymptotic notations (Big O, Omega, Theta), growth rates, worst/average/best case. • Recursion: Call stack, base/recursive cases, recursion tree analysis, space limits. • Bit Manipulation: Bitwise operators, set/unset/toggle bits, bit masking, power of two check. • Linear Arrays & Strings: Traversals, Two Pointers, Sliding Window (fixed/variable). • Hashing: Hash functions, Hash table, HashMap/HashSet, collision handling (Chaining vs Open Addressing). | E3: • Enterprise Architecture: Monolith vs Microservices systems, Maven/Gradle lifecycles, pom.xml. • Spring Core & AOP: IoC, DI, Bean definitions, Spring Boot Aspect-Oriented Programming (AOP): Aspects, Advice, Pointcuts, Join Points, Cross-Cutting Concerns. • Bean Lifecycle: Instantiation, initialization callbacks, destruction, ApplicationContext container. • Dependency Injection Types: Constructor (preferred), Setter, Field injection trade-offs. • Spring Boot: Auto-Configuration (@EnableAutoConfiguration), Starters, Embedded servers (Tomcat). | F3: • System Design Fundamentals: Functional vs Non-Functional requirements (Scalability, Availability, Reliability). • Capacity Estimation: DAU, MAU, Throughput, Storage, Bandwidth, Latency math calculations. • Microservices Architecture: Monolith vs Microservices, Service Discovery (Registry, Client-Side, Server-Side), Microservice Patterns (Database per Service, API Composition, Strangler Pattern, BFF). • Network Routing: DNS resolution flow, CDNs edge caching, Load Balancer algorithms (L4 vs L7). • API Gateway & Proxies: Reverse Proxy vs Forward Proxy, API Gateway routing, rate limiting.
A4: Module 2 | B4: • Constructors: Default vs Parameterized, Constructor Chaining, static & final variables/methods/blocks order. • Access Modifiers & Encapsulation: Private/Default/Protected/Public scope, getters/setters boundaries, immutable classes. • Inheritance & Polymorphism: Single/Multilevel/Hierarchical, Overloading vs Overriding resolution precedence, dynamic dispatch. • Java Generics: Type safety, Generic classes/methods, bounded wildcards (? extends T vs ? super T PECS rule), Type Erasure. • Collections Framework: ArrayList (resizing), LinkedList (doubly linked), HashSet, HashMap (buckets, collision CAS/RB-Tree), TreeSet, TreeMap, Comparable vs Comparator. | C4: • Software Design: Coupling & Cohesion, high cohesion and loose coupling principles. • Dependency Management: Dependency Injection (Constructor, Setter, Field), Inversion of Control (IoC). • SOLID - Single Responsibility Principle (SRP) & Open-Closed Principle (OCP). • SOLID - Liskov Substitution (LSP), Interface Segregation (ISP), Dependency Inversion (DIP). • Design Idioms: DRY (Don't Repeat Yourself), KISS (Keep It Simple), YAGNI (You Aren't Gonna Need It), Separation of Concerns. | D4: • Searching: Linear Search, Binary Search, Binary Search on Answer. • Sorting Basics: Bubble Sort, Selection Sort, Insertion Sort, stability in sorting. • Advanced Sorting: Merge Sort (divide-and-conquer, stable), Quick Sort (pivot partition, unstable). • Linked Lists: Singly, Doubly, Circular Linked Lists; Operations: insertion, deletion, traversal. • Linked Lists Patterns: Fast-Slow pointer (cycle detection, mid), Linked List Reversal. | E4: • REST Architecture: Client-Server, statelessness, uniform interface principles. • HTTP Methods: GET, POST, PUT, PATCH, DELETE semantic differences, HTTP status codes. • Controller Layer: @RestController, @RequestMapping, @PathVariable, @RequestParam. • Request Handling: @RequestBody mapping, ResponseEntity return types, DTO patterns. • Service Layer: Business logic encapsulation, service interfaces vs implementation decoupling. | F4: • Communication Models: Sync (REST, gRPC) vs Async (Message Queues, Pub-Sub), request-response, Webhooks. • Caching Basics: Cache Hit vs Cache Miss, Cache Eviction (LRU, LFU), Cache Invalidation. • Caching Patterns: Cache-Aside, Write-Through, Write-Back, Write-Around. • Distributed Caching: Redis vs Memcached architecture comparison. • Reliability Patterns: Retries, Timeouts, Circuit Breaker state machines, Bulkheads.
A5: Module 3 | B5: • Exception Hierarchy: Throwable -> Error vs Exception, checked vs unchecked exception propagation rules. • Exceptions Handling: try-catch-finally control flow, throws keyword, custom exceptions serialization. • Try-with-resources: AutoCloseable interface, resource leaks prevention, compiler-generated close calls. • Java I/O Streams: Byte streams (InputStream/OutputStream) vs Character streams (Reader/Writer), Buffered Streams. • Serialization: Serializable interface, transient fields, serialVersionUID checking, writeObject/readObject custom hooks. | C5: • Pattern Philosophy: Creational, Structural, Behavioral categorizations, patterns vs frameworks. • Creational - Singleton Pattern: Lazy/Eager, thread-safe double-checked lock, serialization break. • Creational - Factory Pattern: Decoupling object creation, Abstract Factory model. • Creational - Builder Pattern: Immutability, step-by-step construction of complex objects. • Structural - Adapter Pattern: Interface translation, wrapper implementation. | D5: • Stacks: LIFO, implementation (array, list), balanced parentheses check. • Advanced Stacks: Monotonic Stack (Next Greater/Smaller element problems). • Queues: FIFO, Circular Queue, Deque, Priority Queue introduction. • Binary Trees & Trie: Prefix Trees, Trie Insert/Search/Delete, Autocomplete; Traversals (Preorder, Inorder, Postorder). • Binary Search Trees (BST): insertion, deletion, search, BST properties, Lowest Common Ancestor (LCA). | E5: • Data Access & ORM: ORM concepts, JPA specification vs Hibernate implementation. • Entity Mapping: @Entity, @Table, @Column, @Id, @GeneratedValue auto generation strategies. • Relationships: @OneToOne, @OneToMany, @ManyToOne, @ManyToMany database mapping. • Transaction Management: ACID, @Transactional annotation, Propagation, Rollback Rules. • Advanced Database Integration: JpaRepository CRUD, JPQL, Native Queries, Pagination & Sorting, Connection Pooling. | F5: • Database Design: SQL vs NoSQL, CAP Theorem, ACID vs BASE, Database Isolation Levels & Concurrency Anomalies (Dirty, Non-Repeatable, Phantom Reads). • Database Indexing & Tuning: Clustered Index, Non-Clustered Index, Composite Index, Covering Index, B+ Trees; Query Optimization (Execution Plans, Query Cost, Index Selection, N+1 Query). • Database Scaling: Vertical vs Horizontal scaling, Master-Slave replication, Sharding, Consistent Hashing. • Distributed Systems: Leader-Follower, Consistency Models (Strong, Eventual, Quorum Reads/Writes), Distributed Transactions (Two-Phase Commit, Saga-based Transactions). • CQRS & Saga Pattern: Distributed Transactions, Choreography vs Orchestration, Compensation transactions.
A6: Module 4 | B6: • Lambda Expressions: Syntax, closures, functional style code, effectively final variables capture rules. • Functional Interfaces: @FunctionalInterface annotation validation, Predicate, Consumer, Supplier, Function, BiFunction. • Method References: ClassName::methodName syntax, constructor references. • Streams API Intermediate: pipeline processing, filter, map, flatMap, sorted, distinct, limit. • Streams API Terminal: collect, reduce, forEach, count; Optional class; LocalDate/Time API. | C6: • Structural - Decorator Pattern: Dynamic behavior extension without inheritance subclass explosion. • Structural - Proxy Pattern: Access control, lazy loading wrappers. • Behavioral - Strategy Pattern: Dynamic algorithm switching, decoupling conditionals. • Behavioral - Observer Pattern: Subject-Subscriber updates, event listeners modeling. • Behavioral - Template Method Pattern: Algorithm skeletons, code reuse inheritance. | D6: • Heaps: Binary Heap (Min/Max Heap), Heapify, Heap construction, Top-K elements, Heap Sort. • Graphs Representation: Adjacency Matrix, Adjacency List; Graph Traversals (BFS, DFS). • Graphs Connectivity & Cycles: Connected Components, Cycle Detection in directed (DFS stack) & undirected (DSU). • Topological Sort & Advanced Graphs: Strongly Connected Components (Kosaraju, Tarjan), Kahn's algorithm vs DFS. • Shortest Path & MST: Dijkstra's Algorithm (non-negative), Minimum Spanning Trees (Kruskal, Prim, Union-Find Applications). | E6: • Request Validation: Hibernate Validator constraints (@NotNull, @NotBlank, @Size, @Valid). • Global Exception Handling: @RestControllerAdvice, @ExceptionHandler mapping, custom payloads. • Spring Security: Authentication vs Authorization, Security Filter Chain routing. • JWT Authentication: Authentication vs Authorization, Security Filter Chain, UserDetailsService, BCrypt, Token Generation & Validation. • Role-Based Access Control (RBAC): Password encoding (BCrypt), role permissions annotations. | F6: • Event-Driven Architecture (EDA): Events, Producers, Consumers, Event Streams, Message Queue (RabbitMQ). • Distributed Log: Kafka: Topics, Partitions, Consumer Groups, Offsets, DLQ (Dead Letter Queue). • Storage Systems: Blob & Object Storage (S3), File Storage, Block Storage. • Observability: Centralized Logging, Metrics collection, Distributed Tracing, Alerting. • Rate Limiting Algorithms: Token Bucket, Leaky Bucket, Sliding Window Log.
A7: Module 5 | B7: • Concurrency: Process vs Thread, Thread memory layout, Thread lifecycle states, Thread creation (Runnable, Callable, Future). • Java Memory Model (JMM): Happens-Before relationship, Memory Visibility, Instruction Reordering, Atomicity, CAS, Atomic Classes. • Synchronization & Locks: synchronized monitors, volatile visibility, ReentrantLock, ReadWriteLock, deadlocks prevention. • JVM Class Loading & Reflection: Class Loading Lifecycle (Load, Link, Init), ClassLoader Hierarchy, Reflection API, Runtime Metadata, Dynamic Invocation, Custom Annotations. • Garbage Collection (Advanced): Minor GC, Major GC, Full GC, Generational GC, G1GC, ZGC algorithms; ConcurrentHashMap, BlockingQueue (Producer-Consumer). | C7: • Code Smells & Refactoring: God Class, Long Method, Feature Envy, Extract Method, Extract Class. • UML Modeling: Class Diagrams, Sequence Diagrams, Use Case Diagrams interaction modeling. • Domain-Driven Design (DDD): Entity, Value Object, Aggregate, Repository, Bounded Context. • LLD Case Studies: Library Management System, Parking Lot slot allocation concurrency. • LLD Case Studies: Food Ordering System & Movie Booking seat locking transactions handling. | D7: • Disjoint Set Union (DSU): Path compression, Union by rank/size. • Greedy Algorithms: Greedy choice property, Activity Selection, Interval Scheduling. • Backtracking: State space search, subsets, permutations, combinations, N-Queens problem. • Dynamic Programming (DP) Basics: Memoization (top-down) vs Tabulation (bottom-up), State & Transition. • Classic DP: 0/1 Knapsack, Subset Sum, Coin Change, LCS, LIS, space optimization. | E7: • Unit Testing: JUnit test lifecycle, Mockito mocking framework (@Mock, @Spy, @InjectMocks). • Integration Testing: @SpringBootTest, MockMvc, Test Database setup, Database rollback. • Configuration & Logging: application.properties/yml, Profiles, Logging (SLF4J, Logback). • Actuator, Caching & Reactive: Health checks, metrics, Redis caching; Reactive Programming (Reactive Streams, Mono, Flux, WebFlux). • Deployment & DevOps: JAR/WAR packaging, Docker, CI/CD Pipelines (Build, Test, Deploy, Rollback), Kubernetes Basics (Pods, Services, Deployments, Autoscaling). | F7: • Case Studies: URL Shortener design, Database schema, hashing collision handling. • Case Studies: Chat System (WebSockets vs Long Polling), status synchronization. • Case Studies: Video Streaming (CDN caching, chunking, adaptive bitrate), Notification service. • AI System Design: LLM Application Architecture, Vector Embeddings pipelines. • AI Systems Scaling: Vector Databases (FAISS, Pinecone), RAG pipeline retrieval/rerank, AI Agents.
A8: Interview Preparation & Revision | B8: • Core JVM Memory Layout: Explaining Heap vs Stack vs Metaspace memory flags in interviews; how to diagnose OutOfMemoryError (OOM) vs StackOverflowError. • String Constant Pool (SCP): SCP allocation internals, how intern() works, difference between String, StringBuilder, and StringBuffer in thread-safe contexts. • Collection Internals: Deep dive into HashMap collision resolution (Linked List to Red-Black Tree threshold), ArrayList resizing copy overhead, and ConcurrentHashMap lock striping. • Generics PECS Rule: Practical application of Producer Extends Consumer Super wildcard boundaries with code examples. • Multithreading & JMM: Explaining happens-before relationships, volatile memory barriers, CAS operation execution, and atomic classes. • Thread Synchronizations: How synchronized blocks differ from ReentrantLocks, fair vs unfair locks, condition variables, and deadlock avoidance (detection & recovery). • Java Garbage Collection: Explaining minor, major, and full GC events, GC algorithms (G1GC vs ZGC color pointers & load barriers), tuning flags. • JVM Class Loading Lifecycle: ClassLoader hierarchy delegation model, custom ClassLoader creation, static initialization order traps. • Reflection API & Annotations: Performance implications of reflection in frameworks, runtime annotation scanning, dynamic proxy generation. • Stream API Performance: Parallel streams overhead, intermediate lazy evaluation vs terminal operations execution, Optional anti-patterns. | C8: • Encapsulation Boundaries: Explaining data hiding, accessor/mutator validations, and designing strictly immutable classes in interviews. • Abstraction Interface Design: Abstract class vs interface compilation differences, default/static interface methods, and selection criteria. • Polymorphism Precedence: Overriding vs overloading resolution rules, compiler vs runtime binding, dynamic method dispatch execution. • OOP Relationships: Association vs Aggregation vs Composition lifecycle ownership bounds with real-world examples. • High Cohesion & Loose Coupling: Explaining software coupling metrics, refactoring tightly coupled modules, class responsibilities distribution. • SOLID Principles: Violations and refactoring examples for SRP, OCP, LSP, ISP, and DIP in high-level design reviews. • Singleton Pattern: Thread-safe implementations, lazy double-checked locking, serialization breakages, enum singleton benefits. • Factory vs Builder Patterns: Selecting between structural creation abstractions, builder immutability benefits, abstract factory extensions. • Strategy & Observer Patterns: Behavioral design models, decoupling algorithms dynamic switching, subject-subscriber publish flows. • LLD Case Studies: Concurrency controls in parking lots (seat allocations), food order systems state machines, and seat locking mechanisms. | D8: • Asymptotic Complexity: Explaining Big O/Omega/Theta bounds, space complexity stack overhead, and analyzing recursive recurrence relations. • Two Pointers & Sliding Window: Selection metrics for sliding windows (fixed vs dynamic sizes), two pointers collision vs fast-slow flows. • Hashing Collision: Chaining vs open addressing comparisons, hash functions distributions, load factor threshold resizing. • Sorting Algorithms Stability: Stability benefits, Merge Sort vs Quick Sort space-time bounds, pivot selection optimization. • Linked Lists Patterns: Fast-slow pointer cycle detection math, reversal algorithms, in-place node deletions. • Stacks & Monotonic Patterns: Monotonic stack index caching for next greater/smaller element queries, parsing nested syntax formats. • Trees & Traversals: DFS (pre/in/post-order) vs BFS recursive vs iterative executions, Tree height calculations, BST property validations. • Heap & Top-K Problems: Min/Max heap construction complexities, priority queues resizing, heap sort runtime execution bounds. • Graph Cycles & Traversals: Cycle detection in directed graphs (back edges DFS stack) vs undirected graphs (Disjoint Set Union DSU). • Dynamic Programming: Overlapping subproblems detection, state definition, tabulation space optimizations, knapsack variations. | E8: • Spring IoC Container: ApplicationContext bean initialization phases, scopes (singleton, prototype, request), circular dependencies resolution. • Spring Boot Auto-Configuration: How @SpringBootApplication scans packages, conditional bean loading mechanics, and custom starters structure. • Dependency Injection: Constructor injection benefits, field injection risks, qualifiers, and resolving duplicate bean definitions. • Spring AOP Proxying: CGLIB vs JDK dynamic proxies, self-invocation bypass trap, and Aspect lifecycle advice execution order. • JPA & Hibernate Caching: First level vs second level cache, N+1 query problem diagnosis, and lazy loading exceptions. • Spring Transaction Management: Propagation behaviors (REQUIRED vs REQUIRES_NEW), database isolation levels, rollback triggers on checked exceptions. • Global Exception Handling: Designing robust REST responses using @RestControllerAdvice, @ExceptionHandler, and custom error subclasses. • Spring Security Filters: Security Filter Chain execution order, context propagation, JWT stateless validation integration. • Spring Testing Framework: Integration tests speedups, mocking database operations, transaction rollbacks in tests. • Reactive Programming: Spring WebFlux execution model, Mono/Flux streams, non-blocking I/O comparison with traditional MVC. | F8: • Capacity Estimation: Storage, bandwidth, DAU, and throughput calculations for FAANG system design interviews. • Load Balancers & Routing: Layer 4 vs Layer 7 load balancing algorithms, DNS routing, and CDN caching architectures. • API Gateway & Rate Limiting: Rate limiting algorithms (Leaky bucket vs Token bucket vs Sliding window logs), security filters. • Caching Topologies: Cache-Aside vs Write-Through vs Write-Back configurations, cache eviction algorithms (LRU, LFU), cache stampede. • SQL vs NoSQL Selection: CAP theorem constraints, ACID vs BASE model comparisons, database replication topologies. • Consistent Hashing: Hash ring layouts, virtual nodes balance, partitioning, and rehashing avoidance under node counts changes. • Distributed Transactions: Two-Phase Commit (2PC) coordinator locks vs Saga pattern orchestrator/choreography compensation actions. • Message Queue Concurrency: Kafka partition partitions balance, consumer groups offsets tracking, at-least-once vs exactly-once delivery. • High Scale Case Studies: Designing URL shorteners, scalable chat systems, video streaming chunking pipelines. • AI System Architecture: Scalable vector databases, FAISS indices, real-time RAG pipelines scaling, LLM serving caching.

Sheet AI
A1: AI - LEARNING ARCHITECTURE
A2: Module | B2: Machine Learning | C2: Deep Learning | D2: NLP | E2: GenAI | F2: AI Agents
A3: Module 1 | B3: • AI Frameworks: AI vs ML vs DL vs NLP vs GenAI boundaries, ML Lifecycle. • Math - Linear Algebra: Scalars, Vectors, Matrices, Matrix Multiplication, Matrix Inverse. • Math - Probability: Conditional Probability, Bayes Theorem, Joint Probability. • Math - Statistics & Sampling: Mean, Median, Mode, Variance, Covariance, Correlation, Central Limit Theorem, Confidence Intervals. • Math - Distributions & Tests: Normal, Uniform, Binomial, Poisson; Hypothesis Testing, Statistical Tests (t-test, ANOVA, Chi-square), p-values. | C3: • Neural Foundations: Biological vs Artificial Neuron, Perceptron, Multi-Layer Perceptron (MLP). • Activation Functions: Sigmoid, Tanh, ReLU, Leaky ReLU, Softmax. • Loss Functions: Mean Squared Error (MSE), Binary Cross-Entropy, Categorical Cross-Entropy. • Backpropagation: Forward propagation, backward propagation, Chain Rule, Weight updates. • Deep Learning Frameworks: PyTorch vs TensorFlow/Keras basics. | D3: • NLP Foundations & Topic Modeling: Text Corpus, Documents, Tokens, Topic Modeling (LDA). • Preprocessing: Tokenization, Stopword Removal, Stemming, Lemmatization, Text Cleaning. • Text Analytics: Sentiment Analysis, Text Classification. • Named Entity Recognition (NER): Sequence labeling, NER models. • NLP Pipelines: Preprocessing, modeling, post-processing. | E3: • Generative Models: Autoregressive Models, foundation models. • LLM Architectures & Decoding: Tokenizer, Embedding layer, Attention, Decoder Stack, Inference, LLM Decoding Strategies (Greedy, Beam Search, Top-K, Top-p). • Foundation Models: GPT-4, LLaMA, Mixtral, Claude. • Prompt Engineering: Zero-Shot, One-Shot, Few-Shot prompting, System Prompts. • Advanced Prompting: Structured Outputs, Chain of Thought, Prompt Chaining. | F3: • Agent Philosophy: Autonomous agents vs passive LLM generation, execution environments, tool dependency loops. • ReAct Paradigm: Reasoning and Acting cycle, Observation traces, parsing thought-action-observation structures, loop constraints. • Agent Planning: Plan-and-Solve architectures, Goal decomposition, Task planning, dynamic sub-goal generation (BabyAGI pattern). • Function Calling Mechanics: JSON Schema declarations, API argument specifications, LLM response formatting parse errors. • Structured Arguments Mapping: Parsing agent decisions, validation checks, error correction loops, fallback execution handlers.
A4: Module 2 | B4: • Data Extraction: NumPy (Arrays, Broadcasting, Vectorization) and Pandas (Series, DataFrames). • Data Manipulation: Pandas Merge, Join, GroupBy operations. • Data Cleaning: Missing values (MCAR, MAR, MNAR, Imputation), Outlier detection (IQR, Z-Score). • EDA: Univariate, Bivariate, Multivariate analysis; Visualization (Matplotlib, Seaborn). • Feature Engineering: Scaling (Normalization, Standardization), Encoding (One-Hot, Label, Ordinal), Feature Selection. | C4: • Optimization: Gradient Descent variants (Batch, SGD, Mini-batch SGD). • Advanced Optimizers: Adam, RMSprop, Learning Rate schedulers. • Regularization: L1 & L2 Regularization, Dropout, Batch Normalization. • Weight Initialization: Xavier, He initialization methods. • Deep Learning training: Custom training loops, Validation loops. | D4: • Text Vectorization: Bag of Words (BoW), N-Grams. • TF-IDF: Term Frequency, Inverse Document Frequency calculations. • Semantic Space: Vector representations, document similarity. • Similarity Metrics: Cosine Similarity, Jaccard Similarity, Euclidean Distance. • Language Modeling: N-Gram language models, perplexity evaluation. | E4: • Vector Embeddings: Embedding pipelines, text chunking (Fixed vs Semantic). • Vector Databases: FAISS, ChromaDB, Pinecone, Weaviate. • RAG Foundations: Text Chunking, Chunk Overlap, Retrieval, Context Injection, Grounded Generation. • RAG Evaluation: BLEU, ROUGE, Perplexity, RAG Evaluation metrics (Ragas, TruLens). • Context Engineering: Prompt context window limits, context retrieval. | F4: • Short-Term Memory: In-memory session buffers, conversational window limits, sliding window context trimming. • Long-Term Memory: Vector-based semantic recall, user preference profiles storage, semantic retrieval optimization. • LangGraph State Schemas: Defining graph state keys, thread-safe updates, state channel updates, merge policies. • Checkpoints & Persistence: Saving conversation checkpoints, thread configurations, session restoring in LangGraph. • Time Travel Debugging: Accessing historical graph states, state fork execution, interactive session rollbacks.
A5: Module 3 | B5: • Supervised Learning: Linear Regression, Polynomial Regression, Cost function, Gradient Descent. • Classification: Logistic Regression, KNN, Naive Bayes. • Support Vector Machines (SVM): Hyperplanes, margins, kernel trick. • Model Evaluation: Confusion Matrix, Accuracy, Precision, Recall, F1-Score. • Classification Challenges: Class Imbalance handling (SMOTE), ROC-AUC metric. | C5: • Computer Vision: Image Representation (Pixels, Channels RGB/Grayscale). • CNN Foundations: Convolution operation, Kernels, Stride, Padding. • CNN Layers: Pooling (Max, Average), Feature maps, flattening. • CNN Architectures: LeNet, AlexNet, VGG, ResNet (Skip connections). • Computer Vision Tasks: Transfer Learning, Fine-tuning, Object Detection. | D5: • Static Embeddings: Word2Vec (Continuous Bag of Words vs Skip-Gram). • Advanced Static Embeddings: FastText, GloVe, Embedding Spaces. • NLP Sequence Models: Recurrent models (RNN, LSTM, GRU) for text representation. • Seq2Seq NLP: Sequence-to-Sequence models, Machine Translation. • Attention in NLP: Scaled Dot-Product Attention in sequence models. | E5: • Advanced RAG: Hybrid Search (Sparse + Dense), Reranking models. • LangChain Core: Prompt Templates, Chains (LLMChain, SequentialChain). • LangChain Advanced: Router Chains, Memory Systems (Buffer, Summary). • LangChain Integrations: Retrievers, Custom Tools definitions. • Orchestration Frameworks: LangChain Agents, ReAct loop. | F5: • Choreography vs Orchestration: Single agent tools access vs multi-agent coordination models, task delegating protocols. • Hierarchical Supervisor: Supervisor node routing, sub-agent task allocations, supervisor evaluation loops. • Agent-to-Agent (A2A) Protocols: Custom communication message formats, structured JSON messaging protocols, context transferring. • Model Context Protocol (MCP): Client-Server architecture, MCP transports, tool hosting, resource access schemas. • Collaborative Conversational Patterns: Dynamic round-robin chat, group chat managers, state coordination across agents.
A6: Module 4 | B6: • Model Selection: Overfitting vs Underfitting, Bias-Variance Tradeoff. • Validation: Train-Test Split, Cross-Validation (K-Fold, Stratified), Data Leakage. • Decision Trees: Splitting criteria (Shannon Entropy, Gini Impurity, Information Gain). • Ensemble Models: Bagging (Random Forest), Boosting (Gradient Boosting, XGBoost). • Hyperparameter Tuning: Grid Search, Random Search. | C6: • Sequential Data: Time Series, language sequences, temporal dependencies. • Recurrent Neural Networks (RNN): Hidden state updates, Vanishing & Exploding Gradients. • LSTMs: Forget, Input, Output gates architecture. • GRUs: Reset, Update gates architecture. • Sequence-to-Sequence: Encoder-Decoder framework, Attention mechanism introduction. | D6: • Self-Attention: Query, Key, Value vectors; self-attention matrix calculation. • Multi-Head Attention: Parallel attention heads, projections. • Transformer Encoder: Layer normalization, feed-forward network, positional encoding. • Transformer Decoder: Masked self-attention, cross-attention. • Transformer Pre-training: Masked Language Modeling (MLM), Next Sentence Prediction (NSP). | E6: • LangGraph: Nodes, Edges, State management, workflows design. • Agent Architectures: Planning (Plan-and-Solve), Reflection, Memory systems. • Tool Calling: Function Calling, structured arguments mapping. • Agent Protocols: Model Context Protocol (MCP), Agent-to-Agent (A2A). • Orchestration Models: Single Agent vs Multi-Agent coordination. | F6: • LangChain Agent Executors: Deprecated AgentExecutor transition, custom execution loops, callback handlers. • LangGraph Workflows: Building stateful graphs, nodes execution, conditional edges routing, asynchronous execution. • CrewAI Crew Assembly: Agent roles definitions, task dependencies, process flows (sequential vs hierarchical). • AutoGen Conversational Pipelines: Conversational agent agents, human-in-the-loop interactions, code execution environments. • Agent Tool Integration: API wrapping, security sandboxing, credentials isolation, rate-limiting handlers.
A7: Module 5 | B7: • Clustering: K-Means clustering, Hierarchical Clustering (Dendrograms), DBSCAN; Association Rule Learning (Market Basket Analysis). • Dimensionality Reduction: PCA (Principal Component Analysis), t-SNE, Feature Selection methods. • Anomaly Detection & Time Series: Anomaly detection techniques, Time Series Forecasting fundamentals. • Model Deployment & Explainable AI: Explainable AI (SHAP/LIME), model serialization, API serving. • LLMOps/MLOps: Model Deployment, Data Drift, Model Drift monitoring. | C7: • Representation Learning & Self-Supervised: Latent Space, Encoder-Decoder structures, Self-Supervised Learning. • Autoencoders: Reconstruction loss, undercomplete autoencoders. • Variational Autoencoders (VAEs): Generative latent space, KL Divergence. • Generative Adversarial Networks (GANs): Generator, Discriminator, Minimax game. • DLOps: GPU training, checkpointing, model serving, inference. | D7: • Pretrained Models: BERT (Encoder), GPT (Decoder), T5 (Seq2Seq). • Sentence Embeddings: Sentence Transformers, embedding extraction. • Information Retrieval: Sparse (BM25, TF-IDF) vs Dense (vector) retrieval. • Semantic Search: Vector indexing, Vector Databases integration, Reranking. • NLP Applications: Text Summarization, Q&A systems, Chatbots. | E7: • Fine-Tuning & Alignment: PEFT (LoRA, QLoRA), RLHF / Alignment (PPO, DPO). • Quantization: Model compression, Quantization techniques (GPTQ, AWQ, GGUF). • LLMOps: Model serving, endpoints, latency optimization, Guardrails, Bias mitigation. • Local Inference: Ollama, local open-source LLM execution. • Multimodal & Workflows: Multimodal Learning (CLIP, Flamingo), Autonomous Workflows. | F7: • LLM-as-a-Judge Trajectory Evaluation: Reviewing agent steps, action scoring, reasoning trace validation. • LangSmith Tracing: Visualizing execution chains, step latency debugging, run monitoring, cost estimations. • Agent Safety Guardrails: LlamaGuard integration, prompt injections scanning, safety filters before tool calls. • Infinite Loop Mitigations: Max iterations limits, cost budgets tracking, timeout closures, cycle detection. • Production Serving: FastAPI microservices hosting, streaming events formats (Server-Sent Events), concurrency scaling.
A8: Interview Preparation & Revision | B8: • ML Lifecycle & Evaluation: Confusion matrix derivations, accuracy vs precision vs recall vs F1-score optimization targets in interviews. • Math for Machine Learning: Matrix calculus gradients, Bayes theorem applications, and probability distribution parameters. • Linear Models: Gradient Descent optimization, cost functions, regularization penalties (L1 Lasso vs L2 Ridge) bias-variance tradeoff. • Decision Trees & Ensembles: Gini impurity vs Entropy split criteria, bagging vs boosting variance-bias corrections. • Class Imbalance SMOTE: SMOTE nearest neighbor creations, data leakage prevention during cross-validation, cost-sensitive metrics. • Clustering Mechanics: K-Means centroids convergence, Silhouette scores, DBSCAN density-based noise filtering criteria. • Feature Engineering: Normalization vs standardization distributions, one-hot encoding vs target encoding, feature selection metrics. • Time Series & Anomaly: Stationarity checks (ADF tests), ARIMA models, Isolation Forests, Autoencoder thresholds for anomaly. • Explainable AI: SHAP Shapley game theory contributions vs LIME local perturbation model boundaries. • MLOps Serving: Model serialization formats (ONNX, Pickle), data drift vs model drift monitoring, APIs containerizations. | C8: • Neural Network Foundations: Perceptron convergence, forward vs backward propagation math chain rule derivations. • Activation Functions: Sigmoid saturation vanishing gradients vs ReLU dead neurons, Leaky ReLU offsets, Softmax probabilities. • Deep Optimizers: SGD momentum updates, RMSProp running average gradients, Adam learning rates adaptations parameters. • Regularization & Weights: Dropout drop rates, Batch Normalization scales, Xavier vs He weight initializations. • CNN Architectures: Convolution filters padding/strides, pooling reductions, skip connections in ResNet solving gradient degradation. • Recurrent Networks: RNN hidden states vanishing gradients, LSTM forget/input/output gates, GRU update/reset gates configurations. • Autoencoders: Reconstruction loss thresholds, latent space bottlenecks dimension reductions, generative VAE KL-divergence. • GAN Minimax Game: Generator weight updates vs Discriminator binary classifications loss optimization targets. • GPU Training Scaling: Mixed precision training, distributed data parallel implementations, memory bottlenecks diagnostics. • Model Servings: Model weights quantizations, local model inferences parameters, latency checks, pipeline parallelisms. | D8: • Text Preprocessings: Tokenization regex, lemmatization POS tagging, custom stopwords exclusions, noise removals. • Vector Space Models: TF-IDF calculation equations, document similarity Cosine vs Euclidean distances metrics. • Static Word Embeddings: Word2Vec CBOW vs Skip-gram contexts, FastText subwords arrays, GloVe global co-occurrences. • RNN Sequence Structures: Sequence-to-sequence encoder-decoder pipelines, search decoders, alignment scores attention mechanisms. • Self-Attention Mechanics: Query, Key, Value vectors dot-product transformations, scaled dot-product attention equations. • Multi-Head Attention: Parallel projection layers, concatenated heads output dimension mappings. • Transformer Architecture: Layer normalization offsets, positional encodings formulas, masked attention decoders. • Language Models Pretraining: BERT MLM vs NSP objectives, GPT causal decoders, T5 text-to-text transfers. • Vector Indexings: Dense vector database indexing algorithms (HNSW, IVF-PQ), cosine search metrics, rerankers models. • NLP Applications: Topic modeling LDA, NER evaluations, text summarizations metrics (BLEU, ROUGE). | E8: • LLM Decoding Parameters: Greedy search repetitions loops vs Beam Search widths, Top-K/Top-p temperature samplings. • Prompting Strategies: Zero-shot validations, few-shot structures, Chain of Thought logical splits, ReAct agent cycles. • RAG Retrieval Pipelines: Semantic search chunk splits overlap, dense/sparse hybrid search vectors, reranking configurations. • RAG Evaluation Metrics: Faithfulness validations, answer relevance metrics, context recall checks using Ragas frameworks. • LLM Orchestration: LangChain prompt templates, sequential chains, LangGraph state node workflows, agent memory. • Fine-Tuning PEFT: LoRA weight adapters matrices ranks, QLoRA double quantization compression calibrations. • Alignment Reward Loops: RLHF PPO reward model feedbacks vs DPO direct preference optimization calculations. • Quantization Formats: Model weight reductions (GPTQ, AWQ, GGUF), hardware configurations constraints validations. • LLMOps Guardrails: Prompt injections exclusions, guardrails validation APIs, endpoint latency SLA optimizations. • Multimodal Integrations: CLIP image-text alignments, multimodal model embeddings mappings, autonomous agent protocols. | F8: • Agent Reasoning Loops: Comparing ReAct, Plan-and-Solve, and Reflection patterns; debugging infinite loops and token budget exhaustion. • Function Calling & Schemas: Explaining JSON Schema generation for tool calling, handling malformed model arguments, and structured parsing validation. • LangGraph State Management: Designing thread-safe state schemas, merge channels, custom reducer functions, and conflict resolution. • Checkpoints & Time Travel: Implementing state persistence, rolling back to previous state checkpoints, and branching execution paths. • Multi-Agent Communication: Designing supervisor routing patterns vs choreography (round-robin), and passing context between sub-agents. • Model Context Protocol (MCP): Describing MCP client-server architecture, custom tools hosting over SSE/stdio transports, and resource registry. • Agent Memory Strategies: Implementing short-term buffers vs long-term semantic databases, and context window optimization via summary memories. • Execution Security & Sandboxing: Designing secure tool runtime environments, preventing shell execution escapes, and credential isolation. • Trajectory Evaluation (LLMOps): Setting up automated grading for multi-step agent decisions, tracking run histories, and cost/latency profiling. • Guardrails & Injection Defense: Mitigating prompt injections, protecting backend APIs from malicious tool inputs, and boundary validations.

Sheet Core CS
A1: CS CORE - LEARNING ARCHITECTURE
A2: Module | B2: DBMS | C2: SQL | D2: OS | E2: CN
A3: Module 1 | B3: • File System vs DBMS: Data Redundancy, Inconsistency, Isolation issues. • DBMS Functions: Characteristics, advantages, Functions. • Database Architecture: 1-Tier, 2-Tier, Three Schema Architecture, Data Independence. • Relational Model: Relation, schema, tuples, domains. • Database Keys: Super, Candidate, Primary, Foreign, Alternate. | C3: • SQL Overview: Relational Databases vs NoSQL, Popular databases (MySQL, PostgreSQL). • SQL Categories: DDL (CREATE, ALTER, DROP, TRUNCATE), DML (INSERT, UPDATE, DELETE). • SQL Categories & Upserts: DQL (SELECT), TCL (COMMIT, ROLLBACK), Upserts (MERGE, ON CONFLICT, ON DUPLICATE KEY). • Table Constraints: NOT NULL, UNIQUE, PRIMARY KEY, FOREIGN KEY, CHECK, DEFAULT. • Basic Queries: SELECT, ALIAS, DISTINCT, WHERE, Comparison/Logical operators, ORDER BY. | D3: • OS Goals & Boot: OS Functions, Execution Modes, Boot Process (Bootloader -> Kernel -> User Space). • OS Architecture: Monolithic, Microkernel, Hybrid. • Execution Modes: User Mode vs Kernel Mode, System Calls. • Process Management: Process vs Program, States & Transitions, PCB, Context Switching, CPU vs I/O Bound Processes. • Inter-Process Communication (IPC): Shared Memory, Message Queues, Pipes, Sockets; User-level vs Kernel-level threads. | E3: • Network Models & Ethernet: PAN, LAN, MAN, WAN; Topologies; Ethernet Fundamentals. • Network Devices: Repeater, Hub, Bridge, Switch, Router, Gateway. • Reference Models: OSI Reference Model layers (Physical to Application). • TCP/IP Model: Network Access, Internet, Transport, Application layers. • Protocol Layering: Encapsulation, Decapsulation, Protocol Data Units (PDUs).
A4: Module 2 | B4: • ER Modeling: Entities (Strong, Weak), Attributes (Simple, Composite, Derived, Multivalued). • ER Mapping: Cardinality, Participation, ER to Relational schema mapping. • Relational Algebra: Selection, Projection, Union, Set Difference, Cartesian Product. • Relational Joins: Theta, Equi, Natural, Outer Joins. • Database Design: Functional Dependencies, Normal Forms (1NF, 2NF, 3NF, BCNF), Normalization vs Denormalization. | C4: • SQL Functions: Single Row Functions (String, Numeric, Date). • Aggregate Functions: COUNT, SUM, AVG, MIN, MAX. • Grouping: GROUP BY, HAVING, WHERE vs HAVING execution order. • Joins: INNER JOIN, LEFT JOIN, RIGHT JOIN, FULL OUTER JOIN, SELF JOIN, CROSS JOIN. • Join Mechanics: Nested loop join, Hash join, Merge join concepts. | D4: • CPU Scheduling: Goals (Throughput, Turnaround, Waiting, Response time). • Scheduling Algorithms: FCFS, SJF, SRTF, Priority Scheduling, Round Robin. • Advanced Scheduling: Multilevel Queue, Multilevel Feedback Queue Scheduling. • Process Synchronization: Critical Section Problem, Race Conditions, Mutual Exclusion. • Synchronization Locks: Mutex, Spinlocks vs Mutexes, Reader-Writer Locks, Condition Variables, Semaphores (Binary, Counting), Classical problems. | E4: • Physical Layer: Transmission Media, Guided vs Unguided, Bandwidth, Latency, Data Rate. • Data Link Layer: Framing, MAC Address, Error Detection (CRC), Flow Control. • Switching: Switching vs Routing, MAC Learning Tables, Switch Operations. • ARP Protocol: Address Resolution Protocol, ARP broadcast/unicast flow. • Network Tools: ICMP Protocol, Ping, Traceroute.
A5: Module 3 | B5: • Transaction Management: Definition, Lifecycle, States (Active, Committed, Aborted), serial vs concurrent transaction schedules. • ACID & Concurrency: Atomicity, Consistency, Isolation, Durability, Conflict Serializability vs View Serializability. • Concurrency Control: Shared & Exclusive Locks, Two-Phase Locking (2PL), Strict 2PL, Timestamp-Based Concurrency Control. • Concurrency Anomalies: Lost Update, Dirty Read, Non-Repeatable Read, Phantom Read. • Deadlocks & MVCC: Deadlock Handling (Prevention, Detection, Recovery), Multi-Version Concurrency Control (MVCC) basics. | C5: • Subqueries: Single-Row, Multi-Row (IN, ANY, ALL) subqueries. • Advanced Subqueries: Correlated subqueries, Nested subqueries. • Set Operators: UNION, UNION ALL, INTERSECT, EXCEPT. • Database Views: Simple Views, Complex Views, Updatable Views. • Materialized Views: Materialized views, refresh strategies. | D5: • Deadlocks: Necessary Conditions, Prevention, Avoidance (Banker's Algorithm), Detection & Recovery. • Memory Management: Logical vs Physical Addresses, Swapping, Contiguous Allocation. • Memory Partitioning: Fixed Partitioning, Variable Partitioning, Fragmentation, NUMA Basics. • Paging & Segmentation: Frames, Pages, Page Table, Address Translation, Segmentation. • Virtual Memory: Demand Paging, Page Fault, Thrashing, Page Replacement (FIFO, LRU, Optimal), MMU. | E5: • Network Layer: Logical Addressing (IPv4 vs IPv6), IP Address structure. • IP Addressing: Public vs Private IP, Static vs Dynamic IP. • Subnetting: Subnet masks, CIDR notation, Network & Broadcast addresses. • NAT Protocol: Network Address Translation, NAT Types (Static, Dynamic, PAT). • Routing: Routing Tables, Router functions.
A6: Module 4 | B6: • Storage Systems: File Organization (Heap, Sequential, Indexed). • Indexing: Primary, Secondary, Dense, Sparse, Clustered, Non-Clustered indexing. • Index Trees: B-Tree and B+ Tree structures, Indexing node splitting. • Query Processing & Execution: Parsing, Cost-based Optimization, Execution, Buffer Pool Cache. • Execution Plans: Query Execution Plans (EXPLAIN, Execution Tree representation). | C6: • Window Functions: ROW_NUMBER(), RANK(), DENSE_RANK() with PARTITION BY, LEAD(), LAG(). • Advanced Window Functions: FIRST_VALUE(), LAST_VALUE(), JSON Data Handling in SQL Databases. • Common Table Expressions (CTEs): WITH syntax, Recursive CTEs. • Pagination Queries: LIMIT, OFFSET query design. • Application Queries: Reporting queries, dashboard queries, analytics queries. | D6: • Disk & Files: File concepts, directory structures, Memory-Mapped Files. • File Allocation: Allocation methods (Contiguous, Linked, Indexed). • Disk Scheduling: Disk structure, Disk scheduling (FCFS, SSTF, SCAN, C-SCAN). • Device Management: DMA (Direct Memory Access), Interrupts, Buffering vs Caching vs Spooling. • Security: Protection, Access Control. | E6: • Transport Layer: Transport Layer ports, Well Known vs Ephemeral ports. • TCP: Connection-Oriented protocol, Three-Way Handshake, Connection termination (Four-way handshake). • TCP Flow & Congestion: Sliding Window flow control, Congestion Control basics. • UDP: Connectionless protocol, UDP vs TCP trade-offs. • Network Security: VPNs, Firewalls.
A7: Module 5 | B7: • Database Recovery: Failures types, Log-Based Recovery (Write-Ahead Logging). • Database Security & Distributed: Auth, GRANT/REVOKE, Distributed Transactions (Two-Phase Commit). • Integrity Constraints: Entity Integrity, Referential Integrity, Domain Integrity. • NoSQL Models: Key-Value, Document, Column-Family, Graph Databases. • Data Warehousing & OLAP: Data Warehousing, OLTP vs OLAP, Star Schema & Snowflake Schema. | C7: • Indexes: Clustered Index, Non-Clustered Index, Composite Index, Index covering, Index Scan vs Full Table Scan. • Transactions & Locks: Transaction boundaries, ACID properties, Database Locks in SQL Transactions. • Isolation Levels: Read Uncommitted, Read Committed, Repeatable Read, Serializable. • Query Optimization: Query Optimization & Execution Plans, Query Performance Tuning, Partitioned Tables. • Database Programmability: Stored Procedures, User Defined Functions, Triggers. | D7: • Virtualization: Containers vs Virtual Machines, Hypervisors (Type 1 vs Type 2). • Linux Fundamentals: Linux File System Hierarchy, Root Directory Structure. • Linux Shell Commands: pwd, ls, cd, cp, mv, rm, cat, grep, find, chmod, chown, ps, top, kill. • Shell Concepts: Pipes, Redirections, Bash shell variables. • OS Performance: Observability metrics, shell scripting basics. | E7: • Application Protocols: DNS resolution, DHCP IP allocation process. • HTTP Protocol: HTTP request/response, HTTP Methods, Status Codes, HTTP Versions (HTTP/1.1, HTTP/2, HTTP/3). • Advanced Streaming: WebSockets, Server-Sent Events (SSE), gRPC Fundamentals. • Proxy & Load Balancer: Forward vs Reverse Proxy, Load Balancers (Layer 4 vs Layer 7), CDN Architecture. • Network Security & Auth: Same-Origin Policy (SOP), CORS, Authentication (Session, Cookie, Token, OAuth2, JWT), Rate Limiting Basics.
A8: Interview Preparation & Revision | B8: • 3-Schema Architecture: External, conceptual, and physical schema mappings, logical vs physical data independence. • Relational Key Constraints: Primary keys vs Candidate keys, foreign key referential integrity constraints, check constraints. • Relational Algebra: Set operations, selections, projections, cartesian products, natural joins execution behaviors. • Database Normalization: Functional dependencies, 1NF, 2NF, 3NF, BCNF validation anomalies, lossy vs lossless decomposition. • Transaction ACID Properties: Atomicity commit log, consistency rules, isolation concurrency anomalies, durability write-ahead log. • Isolation Levels: Read Uncommitted, Read Committed, Repeatable Read, Serializable; locking mechanisms. • Concurrency Control: Two-Phase Locking (2PL), Strict 2PL deadlock avoidance, Multi-Version Concurrency Control (MVCC) snapshot reads. • B+ Tree Indexing: Node splitting layouts, clustered vs non-clustered indexes search steps, covered indexes. • Database Recovery: Undo/Redo logs, checkpoint operations, write-ahead logging (WAL) protocol rules. • Distributed Databases: Replication topologies (Master-Slave vs Multi-Master), CAP theorem partitions, OLTP vs OLAP star schema. | C8: • SQL Execution Lifecycle: Logical query processing order (FROM -> JOIN -> WHERE -> GROUP BY -> HAVING -> SELECT -> ORDER BY). • Advanced Join Mechanics: Nested loop joins, Hash joins, Merge joins computational complexities. • Subqueries vs CTEs: Correlated subqueries execution costs, recursive CTEs configurations, temp tables. • Window Functions: Partitioning collections, ROW_NUMBER vs RANK vs DENSE_RANK differences, LEAD/LAG data ranges. • Pagination & Upserts: LIMIT/OFFSET optimization, UPSERT formats (ON CONFLICT DO UPDATE, MERGE statements). • Query Indexing Optimizations: Index scan vs index seek selections, composite index column order matching keys. • Transactions Locks: Shared vs exclusive locks, transactional boundaries configurations, locking hints. • SQL Views: Updatable view rules, materialized views caching, refresh strategies execution. • Database Programmability: Stored procedures execution pre-compilation, UDFs performance traps, transactional triggers. • JSON Parsing: Querying JSON payloads, nested document extraction, indexes on JSON properties. | D8: • System Calls: User mode vs kernel mode context switch steps, CPU registers state preservation. • CPU Scheduling: Gantt charts, FCFS, SJF, Round Robin time slice allocations, starvation mitigations. • Process Synchronization: Critical section problems, Mutex vs Semaphore (counting/binary) lock states, Peterson's algorithm. • Deadlocks Prevention: Necessary conditions (Mutual Exclusion, Hold & Wait, No Preemption, Circular Wait), Banker's Algorithm. • Memory Management Paging: Virtual address translation, Page Tables, Translation Lookaside Fund (TLB) hits, page faults. • Page Replacement Algorithms: FIFO anomaly, Least Recently Used (LRU) tracking, Optimal replacement math. • Disk Scheduling: SCAN, C-SCAN, SSTF track travel distances calculations, rotational latency. • Linux Shell Filters: Piping stdout to stdin, grep filters, find selectors, permissions (chmod chown) octal flags. • Inter-Process Communication (IPC): Shared memory segments concurrency vs message passing queues, sockets mappings. • Virtualizations: Container namespaces isolation vs Virtual Machine type-1 hypervisors performance comparisons. | E8: • Layer Encapsulation: Protocol Data Units (PDUs) mapping, TCP segment headers, IP packets, Ethernet frames. • ARP Broadcast Flow: Address Resolution Protocol cache lookup, IP-to-MAC resolution broadcasts, ARP spoofing. • Subnetting & CIDR: Subnet mask CIDR notation math, host counts, broadcast addresses calculations. • NAT & PAT: IP address translation types, port mappings tables, private range routing constraints. • TCP Handshake States: 3-way handshake SYN/ACK sequence numbers, 4-way FIN termination socket closures. • TCP Congestion Control: Congestion window phases (Slow Start, Congestion Avoidance, Fast Retransmit, Fast Recovery). • DNS Resolution Hierarchy: Root servers, TLD servers, Authoritative nameservers lookup flows, caching DNS entries. • HTTP Protocol Versions: HTTP/1.1 keep-alive vs HTTP/2 multiplexing streams vs HTTP/3 QUIC connection migrations. • WebSockets & SSE: WebSockets full-duplex TCP connections vs Server-Sent Events HTTP streams. • CORS & Same-Origin Policy: Same-Origin Policy constraints, CORS preflight request OPTIONS validation headers.

Sheet Aptitude
A1: APTITUDE - LEARNING ARCHITECTURE
A2: Module | B2: Quantitative Aptitude | C2: Verbal Aptitude
